Workbook

Sheet FA
C2: عنوان پروژه | D2: پروژه 400 هزارتنی کاتد مکران
C3: عنوان فرعی پروژه | D3: کارخانه ذوب و اسید فسفریک چابهار
U4: دوره | V4: تولید فسفریک | W4: هزینه عملیاتی | X4: هزینه سرمایه گذاری | Y4: درآمد عملیاتی | Z4: جریان های نقدی بعد از مالیات (یورو) | AB4: جریان نقدی خالص پس از کسر مالیات | AC4: جریان نقد آزاد | AD4: هزینه های عملیاتی | AE4: درآمدهای عملیاتی | AF4: هزینه های سرمایه‌گذاری | AG4: دوره
C5: خلاصه پروژه | V5: (تن) | W5: (یورو) | X5: (یورو) | Y5: (یورو) | AB5: -746033277 | AC5: -746033277 | AD5: 0 | AE5: 0 | AF5: 746033277 | AG5: 0
C6: صنعت | D6: مس و فلزات غیر آهنی | U6: 0 | V6: 0 | W6: 0 | X6: 610250945 | Y6: 0 | Z6: -610167520 | AB6: -447619966 | AC6: -447619966 | AD6: 0 | AE6: 0 | AF6: 447619966 | AG6: 1
C7: زیرصنعت | D7: زنجیره پایین دست صنعت مس | U7: 1 | V7: 726700 | W7: 566826000 | Y7: 799370000 | Z7: 232544000 | AB7: -298413311 | AC7: -298413311 | AD7: 0 | AE7: 0 | AF7: 298413311 | AG7: 2
C8: مکان | D8: منطقه آزاد چابهار | U8: 2 | V8: 894400 | W8: 697632000 | Y8: 983840000 | Z8: 286208000 | AB8: 139072884 | AC8: 139072884 | AD8: 2410227116 | AE8: 2549300000 | AF8: 0 | AG8: 3
C9: درصد پیشرفت پروژه | D9: 0 | U9: 3 | V9: 1118000 | W9: 872040000 | Y9: 1229800000 | Z9: 357760000 | AB9: 171166626 | AC9: 171166626 | AD9: 2966433374 | AE9: 3137600000 | AF9: 0 | AG9: 4
C10: شرح پروژه | D10: تعریف طرح با هدف نیل به تولید سالیانه 1,000,000 تن کاتد مس و 570,000 تن اسید فسفریک در منطقه آزاد چابهار | U10: 4 | V10: 1118000 | W10: 872040000 | Y10: 1229800000 | Z10: 357760000 | AB10: 192562455 | AC10: 192562455 | AD10: 3337237545 | AE10: 3529800000 | AF10: 0 | AG10: 5
C11: وضعیت اجرای پروژه | D11: متوقف | U11: 5 | V11: 1118000 | W11: 872040000 | Y11: 1229800000 | Z11: 357760000 | AB11: 213958283 | AC11: 213958283 | AD11: 3708041717 | AE11: 3922000000 | AF11: 0 | AG11: 6
C12: وضعیت تامین مالی | D12: اقدامی انجام نشده است | U12: 6 | V12: 1118000 | W12: 872040000 | Y12: 1229800000 | Z12: 357760000 | AB12: 213958283 | AC12: 213958283 | AD12: 3708041717 | AE12: 3922000000 | AF12: 0 | AG12: 7
C13: ریسک های اصلی | D13: محدودیت تامین مالی و ماده اولیه | U13: 7 | V13: 1118000 | W13: 872040000 | Y13: 1229800000 | Z13: 357760000 | AB13: 213958283 | AC13: 213958283 | AD13: 3708041717 | AE13: 3922000000 | AF13: 0 | AG13: 8
U14: 8 | V14: 1118000 | W14: 872040000 | Y14: 1229800000 | Z14: 357760000 | AB14: 213958283 | AC14: 213958283 | AD14: 3708041717 | AE14: 3922000000 | AF14: 0 | AG14: 9
C15: هزینه های سرمایه گذاری | U15: 9 | V15: 1118000 | W15: 872040000 | Y15: 1229800000 | Z15: 357760000 | AB15: 213958283 | AC15: 213958283 | AD15: 3708041717 | AE15: 3922000000 | AF15: 0 | AG15: 10
C16: عنوان | D16: مبلغ (میلیون یورو) | U16: 10 | V16: 1118000 | W16: 872040000 | Y16: 1229800000 | Z16: 357760000 | AB16: 213958283 | AC16: 213958283 | AD16: 3708041717 | AE16: 3922000000 | AF16: 0 | AG16: 11
C17: مجموع سرمایه گذاری | D17: 2050 | U17: 11 | V17: 1118000 | W17: 872040000 | Y17: 1229800000 | Z17: 357760000 | AB17: 213958283 | AC17: 213958283 | AD17: 3708041717 | AE17: 3922000000 | AF17: 0 | AG17: 12
C18: مهندسی و دانش فنی | D18: 164 | U18: 12 | V18: 1118000 | W18: 872040000 | Y18: 1229800000 | Z18: 357760000 | AB18: 213958283 | AC18: 213958283 | AD18: 3708041717 | AE18: 3922000000 | AF18: 0 | AG18: 13
C19: ماشین آلات و تجهیزات | D19: 1435 | U19: 13 | V19: 1118000 | W19: 872040000 | Y19: 1229800000 | Z19: 357760000 | AB19: 213958283 | AC19: 213958283 | AD19: 3708041717 | AE19: 3922000000 | AF19: 0 | AG19: 14
C20: ساخت و راه اندازی | D20: 142 | U20: 14 | V20: 1118000 | W20: 872040000 | Y20: 1229800000 | Z20: 357760000 | AB20: 213958283 | AC20: 213958283 | AD20: 3708041717 | AE20: 3922000000 | AF20: 0 | AG20: 15
C21: یوتیلیتی (هزینه ایجاد تاسیسات زیرساختی پشتیبانی تولید) | D21: 155 | U21: 15 | V21: 1118000 | W21: 872040000 | Y21: 1229800000 | Z21: 357760000 | AB21: 213958283 | AC21: 213958283 | AD21: 3708041717 | AE21: 3922000000 | AF21: 0 | AG21: 16
C22: هزینه های پیش از راه اندازی | D22: 100 | U22: 16 | V22: 1118000 | W22: 872040000 | Y22: 1229800000 | Z22: 357760000 | AB22: 213958283 | AC22: 213958283 | AD22: 3708041717 | AE22: 3922000000 | AF22: 0 | AG22: 17
C23: هزینه های پیش بینی نشده | D23: 105 | U23: 17 | V23: 1118000 | W23: 872040000 | Y23: 1229800000 | Z23: 357760000 | AB23: 213958283 | AC23: 213958283 | AD23: 3708041717 | AE23: 3922000000 | AF23: 0 | AG23: 18
C24: سرمایه در گردش | D24: 49 | U24: 18 | V24: 1118000 | W24: 872040000 | Y24: 1229800000 | Z24: 357760000 | AB24: 213958283 | AC24: 213958283 | AD24: 3708041717 | AE24: 3922000000 | AF24: 0 | AG24: 19
U25: 19 | V25: 1118000 | W25: 872040000 | Y25: 1229800000 | Z25: 357760000 | AB25: 213958283 | AC25: 213958283 | AD25: 3708041717 | AE25: 3922000000 | AF25: 0 | AG25: 20
C26: تحلیل سرمایه گذاری | U26: 20 | V26: 1118000 | W26: 872040000 | Y26: 1229800000 | Z26: 357760000 | AB26: 213958283 | AC26: 213958283 | AD26: 3708041717 | AE26: 3922000000 | AF26: 0 | AG26: 21
C27: عنوان | D27: % | AB27: 213958283 | AC27: 213958283 | AD27: 3708041717 | AE27: 3922000000 | AF27: 0 | AG27: 22
C28: درصد ارزی کل سرمایه گذاری | D28: 1
C29: دوره ساخت (سال) | D29: 3
C30: دوره بازگشت سرمایه (سال) | D30: 20 | V30: کل (یورو) | W30: هزینه ریالی (میلیون ریال) | X30: هزینه ارزی ( یورو) | Y30: اقلام هزینه های عملیاتی | AB30: ردیف | AC30: شرح | AD30: یورو در سال
C31: درآمد عملیاتی سالانه (EBIT) | D31: 735.96 | V31: 622782692 | W31: 26655010 | X31: 579069217 | Y31: مواد اولیه و مصرفی | AB31: 1 | AC31: کنسانتره | AD31: 3253663214
C32: درآمد خالص سالانه | D32: 551.97 | V32: 35853214 | W32: 15775414 | X32: 0 | Y32: یوتیلیتی و تاسیسات مصرفی | AB32: 2 | AC32: مواد مصرفی | AD32: 29874220
C33: نرخ بازده داخلی (IRR) | D33: 0.2303 | V33: 64288522 | W33: 28286950 | X33: 0 | Y33: تعمیر و نگهداری | AB33: 3 | AC33: زغالسنگ | AD33: 17042
C34: خالص ارزش فعلی پروژه با نرخ تنزیل 12% (NPV) | D34: 2,067 میلیون یورو | V34: 9890542 | W34: 4351838 | X34: 0 | Y34: نیروی انسانی | AB34: 4 | AC34: گاز طبیعی | AD34: 818730
V35: 98658155 | W35: 14687455 | X35: 67235903 | Y35: هزینه سربار | AB35: 5 | AC35: برق | AD35: 8273828
C36: جزئیات درآمدی | V36: 12363177 | W36: 5439798 | X36: 0 | Y36: هزینه بازاریابی و فروش | AB36: 6 | AC36: آب | AD36: 314014
C37: نام محصول | D37: ظرفیت تولید سالانه | V37: 15948499 | W37: 1631939 | X37: 12606732 | Y37: قطعات یدکی | AB37: 7 | AC37: نیروی کار مستقیم | AD37: 36743494
C38: کاتد مس | D38: 400,000 تن در سال | V38: 11225765 | W38: 3263879 | X38: 3922094 | Y38: هزینه های پیش بینی نشده | AB38: 8 | AC38: نگهداری (5 درصد) | AD38: 28677205
C39: اسید سولفوریک | D39: 1,720,000 تن در سال | V39: 871010565 | W39: 100092283 | X39: 662833947 | Y39: کل | AB39: 9 | AC39: هزینه های پیشبینی نشده | AD39: 9991544
C40: اسید فسفریک | D40: 570,000 تن در سال (P2O5 100%) | AB40: مجموع | AD40: 3368526666
C41: لجن آندی | D41: 1,200 تن در سال
...

Sheet EN
B2: Project Title: | C2: Makran 400,000 ton/year cathode project
B3: Project Sub Title: | C3: Chabahar Smelting and Phosphoric Acid Complex
B5: Project summary
B6: Industry: | C6: Copper and Non-Ferrous Metals
B7: Sub-industry: | C7: Downstream Copper Industry
B8: Location: | C8: Chabahar Free Zone
B9: Project Completion Percentage: | C9: 0
B10: project description | C10: defined with the goal of achieving annual production of 1,000,000 tons of copper cathode for NICICo
B11: Project Execution status | C11: Stopped
B12: Financing status | C12: No action has been taken
B13: Key risks | C13: Financial and feedstock supply limitations
B15: CapEx Breakdown
B16: Category | C16: amount
B17: Total investment | C17: =FA!D17
B18: Engineering & know-how | C18: =FA!D18
B19: equipment | C19: =FA!D19
B20: construction and commissioning | C20: =FA!D20
B21: Utilities | C21: =FA!D21
B22: Pre-operation expenses | C22: =FA!D22
B23: Contingencies | C23: =FA!D23
B24: working capital | C24: =FA!D24
B26: Investment analysis
B27: metric | C27: value
B28: % investment in foreign currency | C28: =FA!D28
B29: construction period (years) | C29: 3
B30: payback period (years) | C30: 20
B31: operating income (EBIT)
B32: Net income
B33: Internal rate of return (IRR) | C33: 0.23
B34: NPV at 10% Discount rate | C34: 2,067 million Euro
B36: Revenue Breakdown
B37: Product | C37: Capacity (Unit of measure)
B38: Copper Cathode | C38: 400,000 ton/year
B39: Sulphuric Acid | C39: 1,720,000 ton/year
B40: Phosphoric Acid | C40: 570,000 ton/year
B41: Anode Slime | C41: 1,200 ton/year
B42: annual Revenue | C42: 5,150 million Euro
B43: % revenue in Foreign currency | C43: 100
B44: Target Market | C44: Export
B46: Expenses breakdown
...
